<?xml version="1.0" ?>
<!-- =================================================================================== -->
<!-- |    This document was autogenerated by xacro from ecocar.xacro                   | -->
<!-- |    EDITING THIS FILE BY HAND IS NOT RECOMMENDED                                 | -->
<!-- =================================================================================== -->
<!-- =================================================================================== -->
<!-- |    DTU Ecocar URFD                                                              | -->
<!-- |    Notes: height, body mass and wheel mass are not the actual values            | -->
<!-- |    Author: Thomas Passer Jensen (s134234@student.dtu.dk)                        | -->
<!-- =================================================================================== -->
<robot name="ecocar" xmlns:xacro="http://www.ros.org/wiki/xacro">
  <!-- Begin Gazebo definitions -->
  <!-- ros_control plugin -->
  <gazebo>
    <plugin filename="libgazebo_ros_control.so" name="gazebo_ros_control">
      <robotNamespace>/ecocar</robotNamespace>
      <robotSimType>gazebo_ros_control/DefaultRobotHWSim</robotSimType>
    </plugin>
  </gazebo>
  <!-- Rear left wheel -->
  <gazebo reference="wheel_rear_left">

  </gazebo>
  <!-- Rear right wheel -->
  <gazebo reference="wheel_rear_right">

  </gazebo>
  <!-- Front left axle -->
  <gazebo reference="front_left_axle">

  </gazebo>
  <!-- Front right axle -->
  <gazebo reference="front_right_axle">

  </gazebo>
  <!-- Front left wheel -->
  <gazebo reference="front_left_wheel">

  </gazebo>
  <!-- Front right wheel -->
  <gazebo reference="front_right_wheel">

  </gazebo>
  <!-- End Gazebo definitions -->
  <link name="base_link">
    <inertial>
      <mass value="10"/>
      <inertia ixx="10.2348075" ixy="0.0" ixz="0.0" iyy="2.07900333333" iyz="0.0" izz="10.9638108333"/>
    </inertial>
    <visual>
      <origin rpy="0 0 -1.57079632679" xyz="-0.1 0 0.1"/>
      <geometry>
        <mesh filename="package://ecocar_description/meshes/ecocar_texture.dae" scale="1 1 1"/>
      </geometry>
    </visual>
    <collision>
      <origin rpy="0 0 -1.57079632679" xyz="-0.1 0 0.1"/>
      <geometry>
        <mesh filename="package://ecocar_description/meshes/ecocar16.dae" scale="1 1 1"/>
      </geometry>
    </collision>
  </link>
  <link name="wheel_rear_left">
    <inertial>
      <mass value="1"/>
      <inertia ixx="0.0228494233333" ixy="0.0" ixz="0.0" iyy="0.0228494233333" iyz="0.0" izz="0.03903218"/>
    </inertial>
    <visual>
      <origin rpy="0 1.57079632679 0" xyz="0 0 0"/>
      <geometry>
        <mesh filename="package://ecocar_description/meshes/wheel_meshlab.dae" scale="0.001 0.001 0.001"/>
      </geometry>
    </visual>
    <collision>
      <geometry>
        <cylinder length="0.2" radius="0.2794"/>
      </geometry>
    </collision>
  </link>
  <link name="wheel_rear_right">
    <inertial>
      <mass value="1"/>
      <inertia ixx="0.0228494233333" ixy="0.0" ixz="0.0" iyy="0.0228494233333" iyz="0.0" izz="0.03903218"/>
    </inertial>
    <visual>
      <origin rpy="0 -1.57079632679 0" xyz="0 0 0"/>
      <geometry>
        <mesh filename="package://ecocar_description/meshes/wheel_meshlab.dae" scale="0.001 0.001 0.001"/>
      </geometry>
    </visual>
    <collision>
      <geometry>
        <cylinder length="0.2" radius="0.2794"/>
      </geometry>
    </collision>
  </link>
  <joint name="base_to_wheel_rear_left" type="continuous">
    <parent link="base_link"/>
    <child link="wheel_rear_left"/>
    <axis xyz="0 0 1"/>
    <origin rpy="-1.57079632679 0 0" xyz="-0.758 0.4 0.2794"/>
  </joint>
  <joint name="base_to_wheel_rear_right" type="continuous">
    <parent link="base_link"/>
    <child link="wheel_rear_right"/>
    <axis xyz="0 0 1"/>
    <origin rpy="-1.57079632679 0 0" xyz="-0.758 -0.4 0.2794"/>
  </joint>
  <link name="front_left_axle">
    <inertial>
      <mass value="1"/>
      <inertia ixx="0.004" ixy="0.0" ixz="0.0" iyy="0.004" iyz="0.0" izz="0.004"/>
    </inertial>
  </link>
  <link name="front_right_axle">
    <inertial>
      <mass value="1"/>
      <inertia ixx="0.004" ixy="0.0" ixz="0.0" iyy="0.004" iyz="0.0" izz="0.004"/>
    </inertial>
  </link>
  <link name="front_left_wheel">
    <inertial>
      <mass value="1"/>
      <inertia ixx="0.0228494233333" ixy="0.0" ixz="0.0" iyy="0.0228494233333" iyz="0.0" izz="0.03903218"/>
    </inertial>
    <visual>
      <origin rpy="0 1.57079632679 0" xyz="0 0 0"/>
      <geometry>
        <mesh filename="package://ecocar_description/meshes/wheel_meshlab.dae" scale="0.001 0.001 0.001"/>
      </geometry>
    </visual>
    <collision>
      <geometry>
        <cylinder length="0.2" radius="0.2794"/>
      </geometry>
    </collision>
  </link>
  <link name="front_right_wheel">
    <inertial>
      <mass value="1"/>
      <inertia ixx="0.0228494233333" ixy="0.0" ixz="0.0" iyy="0.0228494233333" iyz="0.0" izz="0.03903218"/>
    </inertial>
    <visual>
      <origin rpy="0 1.57079632679 0" xyz="0 0 0"/>
      <geometry>
        <mesh filename="package://ecocar_description/meshes/wheel_meshlab.dae" scale="0.001 0.001 0.001"/>
      </geometry>
    </visual>
    <collision>
      <geometry>
        <cylinder length="0.2" radius="0.2794"/>
      </geometry>
    </collision>
  </link>
  <joint name="front_left_steer_joint" type="continuous">
    <parent link="base_link"/>
    <child link="front_left_axle"/>
    <origin rpy="0 0 0" xyz="0.758 0.542 0.2794"/>
    <axis xyz="0 0 1"/>
    <limit effort="10000000" lower="-0.785398163397" upper="0.785398163397" velocity="1000000"/>
  </joint>
  <joint name="front_right_steer_joint" type="continuous">
    <parent link="base_link"/>
    <child link="front_right_axle"/>
    <origin rpy="0 0 0" xyz="0.758 -0.542 0.2794"/>
    <axis xyz="0 0 1"/>
    <limit effort="10000000" lower="-0.785398163397" upper="0.785398163397" velocity="1000000"/>
  </joint>
  <joint name="front_left_wheel_joint" type="continuous">
    <parent link="front_left_axle"/>
    <child link="front_left_wheel"/>
    <origin rpy="-1.57079632679 0 0" xyz="0 0 0"/>
    <axis xyz="0 0 1"/>
  </joint>
  <joint name="front_right_wheel_joint" type="continuous">
    <parent link="front_right_axle"/>
    <child link="front_right_wheel"/>
    <origin rpy="-1.57079632679 0 0" xyz="0 0 0"/>
    <axis xyz="0 0 1"/>
  </joint>
</robot>

